Workbook

Sheet 汇总
A1: 金湖展贸中心智能控制系统 · BOM 汇总
A2: 设备物料清单 总计 · 数据来源现场实测 · 更新日期 2026-05-21
A4: # | B4: 子系统 | C4: Sheet 名 | D4: 小计 (¥) | E4: 说明
A5: 1 | B5: 主控 (中控主机 + 平板) | C5: 1-主控 | D5: ='1-主控'!I10 | E5: 占美 GK9000 + 2 台 1920×1200 平板
A6: 2 | B6: DALI 灯光 (网关 + 13 台 HLG 电源 + 3 台 LT-84A) | C6: 2-灯光 | D6: ='2-灯光'!I27 | E6: 19 路调光 · 25 个 DALI 地址 · CY-DALI64A 统管
A7: 3 | B7: LED 大屏 (控制器 + 接收卡, 屏体单独估) | C7: 3-LED大屏 | D7: ='3-LED大屏'!I11 | E7: 诺瓦 VX1000 + 100 张接收卡, 屏体待报价
A8: 4 | B8: 音响 (DSP + 功放 + 喇叭 + 麦克风) | C8: 4-音响 | D8: ='4-音响'!I14 | E8: DSPPA MAG6816 + 4 区 + 舒尔无线麦
A9: 5 | B9: 空调 (2 外机 + 网关 + 22 内机 + 22 线控) | C9: 5-空调 | D9: ='5-空调'!I36 | E9: 奥克斯 ARV-X9 商用 VRF · 76.3kW 总容量
A10: 6 | B10: 网络 (交换机/路由器/AP/UPS/机柜) | C10: 6-网络 | D10: ='6-网络'!I17 | E10: H3C + TP-Link + 山特 UPS + 图腾机柜
A11: 7 | B11: 线缆耗材 | C11: 7-线缆 | D11: ='7-线缆'!I22 | E11: 网线/DALI/RS485/XYE/喇叭线/XLR 卡侬
A12: 8 | B12: 工具与调试 | C12: 8-工具 | D12: ='8-工具'!I13 | E12: 万用表/Modbus Poll/Wireshark/标签机
A13: 项目合计 (不含 LED 屏体) | D13: =SUM(D5:D12) | E13: LED 屏体 + 灯具本体另行采购
A16: ■ 重要备注
A17: 1. LED 大屏屏体 (接收卡 + LED 模组) 按面积单独询价, 一般占整体预算 30-50%, 表中按 100 张接收卡示意.
A18: 2. 灯具本体 (筒灯/射灯/吸顶灯/灯带) 由土建/装修预算覆盖, 此 BOM 仅含智能化控制部分.
A19: 3. 灯具采购**必须要求 0-10V 调光款** (筒灯/射灯/吸顶灯), 单价比普通款 +10-15%.
A20: 4. 灯带按 DC 24V / 10W/m 主流款采购.
A21: 5. 空调外机 + 内机 + 网关必须**同品牌** (奥克斯), 不能跨厂混搭.
A22: 6. LED 发送卡 (VX1000) + 接收卡必须**同品牌** (诺瓦), LED 模组任意 (HUB75 通用).
A23: 7. 数量"1"配"按面积/按数量"备注的项, 单价默认 1 个单元 (m²/台/张), 实际下单按规模乘.
A24: 8. 单价为渠道参考价, 批量采购可低 10-20%.
A25: 9. 待厂家最终确认: VX1000 vs V2460 (LED) · CCM-270B 是否兼容 ARV-X9 (空调).
A28: ■ 关联文档 (https://cnjinhu.top/jinhu/docs/)
A29: 设备总清单 (本表 .md 版本) | B29: https://cnjinhu.top/jinhu/docs/#EQUIPMENT_LIST
A30: 灯光最终选型 (含 DALI 寻址表) | B30: https://cnjinhu.top/jinhu/docs/#LIGHTING_FINAL_SELECTION
A31: 驱动模块明细 (功率/余量) | B31: https://cnjinhu.top/jinhu/docs/#LIGHTING_DRIVER_DETAILS
A32: 空调功能区 (场景配置) | B32: https://cnjinhu.top/jinhu/docs/#HVAC_ZONES
A33: DALI 现场施工 SOP | B33: https://cnjinhu.top/jinhu/docs/#DALI_FIELD_INSTALL
A34: 空调现场施工 SOP | B34: https://cnjinhu.top/jinhu/docs/#HVAC_FIELD_INSTALL
A35: 音响现场施工 SOP | B35: https://cnjinhu.top/jinhu/docs/#AUDIO_FIELD_INSTALL
A36: 无线网络方案 | B36: https://cnjinhu.top/jinhu/docs/#WIRELESS_NETWORK

Sheet 1-主控
A1: 金湖展贸中心智能控制系统 · 1. 主控设备
A2: BOM 物料明细 · 更新日期 2026-05-21
A4: 编号 | B4: 设备类别 | C4: 中文设备名 | D4: 厂家中文名 | E4: 厂家英文 | F4: 型号 | G4: 数量 | H4: 单价(¥) | I4: 小计(¥) | J4: 规格备注 | K4: 安装位置
A5: 1.1 中控主机
A6: HOST-1 | B6: 主控 | C6: 工控机 (中控主机) | D6: 占美 | E6: GIADA | F6: GK9000 | G6: 1 | H6: 7000 | I6: =G6*H6 | J6: i7-10750H · 16GB · 1TB SSD · 6×COM · 2×RJ45 · Win10 Pro | K6: 1F 弱电机柜
A7: 1.2 控制平板
A8: TABLET-1F | B8: 主控 | C8: 控制平板 (1F 主控台) | D8: 任意 (推荐联想/华为/三星) | E8: — | F8: 安卓 1920×1200 或 iPad | G8: 1 | H8: 2500 | I8: =G8*H8 | J8: 10.5+ 寸 · WiFi · PWA 添加到主屏 | K8: 1F 前厅控制台
A9: TABLET-2F | B9: 主控 | C9: 控制平板 (2F 副控台, 可选) | D9: 任意 | E9: — | F9: 同上 | G9: 1 | H9: 2500 | I9: =G9*H9 | J9: 可选, 2F 服务台用 | K9: 2F 服务台
A10: 本表合计 | I10: =SUM(I5:I9)

Sheet 2-灯光
A1: 金湖展贸中心智能控制系统 · 2. DALI 灯光子系统
A2: BOM 物料明细 · 更新日期 2026-05-21
A4: 编号 | B4: 设备类别 | C4: 中文设备名 | D4: 厂家中文名 | E4: 厂家英文 | F4: 型号 | G4: 数量 | H4: 单价(¥) | I4: 小计(¥) | J4: 规格备注 | K4: 安装位置
A5: 2.1 网关与协议转换
A6: CONV-RTU-1 | B6: 灯光 | C6: RS485↔TCP 协议转换器 | D6: 有人物联网 | E6: USR IoT | F6: USR-TCP232-410S | G6: 1 | H6: 150 | I6: =G6*H6 | J6: DC 12V · 1×RS485 · 1×RJ45 | K6: 1F 弱电机柜
A7: GW-DALI-1 | B7: 灯光 | C7: DALI 控制网关 | D7: 元创智控 | E7: — | F7: CY-DALI64A | G7: 1 | H7: 1000 | I7: =G7*H7 | J7: 单路 DALI 64 地址 · Modbus RTU · DIN 35mm | K7: 1F 弱电机柜
A8: 2.2 LED 灯带 DALI 恒压电源 (DC 24V, MEANWELL 明纬)
A9: DRV-HLG-1 | B9: 灯光 | C9: LED 大功率电源 480W (前厅灯带) | D9: 明纬 | E9: MEANWELL | F9: HLG-480H-24DA | G9: 1 | H9: 400 | I9: =G9*H9 | J9: 480W @ DC 24V/20A · DALI 2.0 · IP67 · 5 年保 | K9: 1F 公共电箱 F101
A10: DRV-HLG-2 | B10: 灯光 | C10: LED 大功率电源 185W (重点灯带) | D10: 明纬 | E10: MEANWELL | F10: HLG-185H-24DA | G10: 1 | H10: 280 | I10: =G10*H10 | J10: 187W @ DC 24V/7.8A · DALI 2.0 · IP67 | K10: 1F 公共电箱 F101
A11: DRV-HLG-3 | B11: 灯光 | C11: LED 大功率电源 150W (园区灯带) | D11: 明纬 | E11: MEANWELL | F11: HLG-150H-24DA | G11: 1 | H11: 270 | I11: =G11*H11 | J11: 150W @ DC 24V/6.25A · DALI 2.0 · IP67 | K11: 1F 公共电箱 F101
A12: DRV-HLG-4 | B12: 灯光 | C12: LED 大功率电源 480W (走廊灯带#1, 头段) | D12: 明纬 | E12: MEANWELL | F12: HLG-480H-24DA | G12: 1 | H12: 400 | I12: =G12*H12 | J12: 走廊 130m 灯带 3 台并联中段注入 | K12: 1F 公共电箱 F101
A13: DRV-HLG-5 | B13: 灯光 | C13: LED 大功率电源 480W (走廊灯带#2, 中段) | D13: 明纬 | E13: MEANWELL | F13: HLG-480H-24DA | G13: 1 | H13: 400 | I13: =G13*H13 | J13: 走廊中段 65m 处注入 | K13: 1F 走廊中段电箱
A14: DRV-HLG-6 | B14: 灯光 | C14: LED 大功率电源 480W (走廊灯带#3, 尾段) | D14: 明纬 | E14: MEANWELL | F14: HLG-480H-24DA | G14: 1 | H14: 400 | I14: =G14*H14 | J14: 走廊尾段注入 | K14: 1F 走廊尾端电箱
A15: DRV-HLG-7 | B15: 灯光 | C15: LED 大功率电源 480W (R7 灯带#1) | D15: 明纬 | E15: MEANWELL | F15: HLG-480H-24DA | G15: 1 | H15: 400 | I15: =G15*H15 | J15: 重点照明灯带 80m / 800W 拆 2 台并联 | K15: 1F 公共电箱 F101
A16: DRV-HLG-8 | B16: 灯光 | C16: LED 大功率电源 480W (R7 灯带#2) | D16: 明纬 | E16: MEANWELL | F16: HLG-480H-24DA | G16: 1 | H16: 400 | I16: =G16*H16 | J16: 同上 #2 | K16: 1F 公共电箱 F101
A17: DRV-HLG-9 | B17: 灯光 | C17: LED 大功率电源 240W (F102 灯带) | D17: 明纬 | E17: MEANWELL | F17: HLG-240H-24DA | G17: 1 | H17: 320 | I17: =G17*H17 | J17: 240W @ DC 24V/10A · 企业展位灯带 20m | K17: 1F 企业展位区电箱 F102
A18: DRV-HLG-10 | B18: 灯光 | C18: LED 大功率电源 240W (F104 灯带) | D18: 明纬 | E18: MEANWELL | F18: HLG-240H-24DA | G18: 1 | H18: 320 | I18: =G18*H18 | J18: 物贸交易展示区灯带 20m | K18: 1F 物贸交易电箱 F104
A19: DRV-HLG-11 | B19: 灯光 | C19: LED 大功率电源 480W (2F 走廊#1) | D19: 明纬 | E19: MEANWELL | F19: HLG-480H-24DA | G19: 1 | H19: 400 | I19: =G19*H19 | J19: 2F 走廊灯带 85m / 900W 拆 2 台并联 | K19: 2F 公共电箱 F201
A20: DRV-HLG-12 | B20: 灯光 | C20: LED 大功率电源 480W (2F 走廊#2) | D20: 明纬 | E20: MEANWELL | F20: HLG-480H-24DA | G20: 1 | H20: 400 | I20: =G20*H20 | J20: 同上 #2 | K20: 2F 公共电箱 F201
... A22: DRV-HLG-13b | B22: 灯光 | C22: LED 大功率电源 320W (灯箱#2) | D22: 明纬 | E22: MEANWELL | F22: HLG-320H-24DA | G22: 1 | H22: 450 | I22: =G22*H22 | J22: 同上 #2 | K22: 1F 公共电箱 F101
A23: 2.3 灯具 0-10V 调光转换器 (DALI 转 0-10V, LTECH 雷特)
A24: CONV-LT-1 | B24: 灯光 | C24: DALI 转 0-10V 信号转换器 #1 | D24: 雷特科技 | E24: LTECH | F24: LT-84A | G24: 1 | H24: 600 | I24: =G24*H24 | J24: 4 路 0-10V · AC 220V · 5 年保 · 三合一输入 | K24: 1F 公共电箱 F101
A25: CONV-LT-2 | B25: 灯光 | C25: DALI 转 0-10V 信号转换器 #2 | D25: 雷特科技 | E25: LTECH | F25: LT-84A | G25: 1 | H25: 600 | I25: =G25*H25 | J25: 同上, 覆盖 F101-R7 + F103 + F201 | K25: 1F 综合展销电箱 F103
A26: CONV-LT-3 | B26: 灯光 | C26: DALI 转 0-10V 信号转换器 #3 | D26: 雷特科技 | E26: LTECH | F26: LT-84A | G26: 1 | H26: 600 | I26: =G26*H26 | J26: 同上, 覆盖 2F 服务/办公/研究/指挥 | K26: 2F 公共电箱 F201
A27: 本表合计 | I27: =SUM(I5:I26)

Sheet 3-LED大屏
A1: 金湖展贸中心智能控制系统 · 3. LED 大屏子系统
A2: BOM 物料明细 · 更新日期 2026-05-21
A4: 编号 | B4: 设备类别 | C4: 中文设备名 | D4: 厂家中文名 | E4: 厂家英文 | F4: 型号 | G4: 数量 | H4: 单价(¥) | I4: 小计(¥) | J4: 规格备注 | K4: 安装位置
A5: 3.1 LED 大屏控制器 (诺瓦 NovaStar)
A6: LED-CTRL-1 | B6: LED | C6: LED 视频处理器 (发送卡 + 拼接) | D6: 诺瓦星云 | E6: NovaStar | F6: VX1000 (待最终确认) | G6: 1 | H6: 18000 | I6: =G6*H6 | J6: 6.5M 像素 · 10×RJ45 · HDMI×2+DVI+SDI · 1U 机架 | K6: 1F 主控室机柜
A7: LED-PLAYER-1 | B7: LED | C7: LED 播控主机 (媒体播放) | D7: 英特尔 | E7: Intel | F7: NUC11 | G7: 1 | H7: 4000 | I7: =G7*H7 | J7: Win10 + ViPlex Express · HDMI 输出到 VX1000 | K7: 1F 主控室机柜
A8: 3.2 LED 屏体配件 (按面积单独询价)
A9: LED-RECV | B9: LED | C9: LED 接收卡 (按张计) | D9: 诺瓦星云 | E9: NovaStar | F9: A4s / A8s | G9: 100 | H9: 200 | I9: =G9*H9 | J9: 每张接 65 万像素 LED 模组, 数量按屏估算 | K9: 屏幕内部
A10: LED-MODULE | B10: LED | C10: LED 显示模组 (按㎡计) | D10: 灯具厂家 | E10: — | F10: 按 P 间距选 P1.8/P2.5/P3 | G10: 1 | H10: 0 | I10: =G10*H10 | J10: AC 220V LED 模组, 按现场面积报价 | K10: 1F/2F 大屏区
A11: 本表合计 | I11: =SUM(I5:I10)

Sheet 4-音响
A1: 金湖展贸中心智能控制系统 · 4. 音响子系统
A2: BOM 物料明细 · 更新日期 2026-05-21
A4: 编号 | B4: 设备类别 | C4: 中文设备名 | D4: 厂家中文名 | E4: 厂家英文 | F4: 型号 | G4: 数量 | H4: 单价(¥) | I4: 小计(¥) | J4: 规格备注 | K4: 安装位置
A5: 4.1 DSP 数字音频处理器
A6: AUDIO-DSP-1 | B6: 音响 | C6: 数字音频处理器 (DSP) | D6: 迪士普 | E6: DSPPA | F6: MAG6816 | G6: 1 | H6: 3200 | I6: =G6*H6 | J6: 4 路分区输出 · 网络控制 · MIC 优先压低 | K6: 1F 主控室机柜
A7: 4.2 功放与喇叭
A8: AUDIO-AMP | B8: 音响 | C8: 定阻功放 (按分区配) | D8: 同 DSP 品牌 | E8: — | F8: 按功率匹配 (推荐 4Ω/100W) | G8: 4 | H8: 1800 | I8: =G8*H8 | J8: 每个分区 1 台, 共 4 区 | K8: 1F 弱电机柜
A9: AUDIO-SPK | B9: 音响 | C9: 吸顶喇叭 (按区域配) | D9: 任意 | E9: — | F9: 吸顶 6.5"/8" 或壁挂 30-60W | G9: 30 | H9: 250 | I9: =G9*H9 | J9: 按区域天花/墙面布置 | K9: 各区域天花/墙面
A10: 4.3 麦克风 (无线 UHF, 推荐方案见 docs/WIRELESS_NETWORK.md)
A11: AUDIO-MIC-1 | B11: 音响 | C11: 无线手持麦克风 (一拖二) | D11: 舒尔 | E11: Shure | F11: BLX24/PG58 | G11: 1 | H11: 5000 | I11: =G11*H11 | J11: UHF 470-510 MHz · 2 支手持 | K11: 接待区/路演区
A12: AUDIO-MIC-2 | B12: 音响 | C12: 无线腰挂领夹麦 (可选) | D12: 得胜 | E12: Takstar | F12: TS-9550 | G12: 1 | H12: 1200 | I12: =G12*H12 | J12: UHF 国标 · 导览/路演移动用 (可选) | K12: 路演区
A13: AUDIO-MIC-3 | B13: 音响 | C13: 鹅颈会议麦 (可选, 接待用) | D13: 舒尔 | E13: Shure | F13: MX418 | G13: 2 | H13: 3500 | I13: =G13*H13 | J13: 主席台会议用 (可选) | K13: 2F 会议室
A14: 本表合计 | I14: =SUM(I5:I13)

Sheet 5-空调
A1: 金湖展贸中心智能控制系统 · 5. 中央空调子系统 (奥克斯商用 VRF, 22 内机)
A2: BOM 物料明细 · 更新日期 2026-05-21
A4: 编号 | B4: 设备类别 | C4: 中文设备名 | D4: 厂家中文名 | E4: 厂家英文 | F4: 型号 | G4: 数量 | H4: 单价(¥) | I4: 小计(¥) | J4: 规格备注 | K4: 安装位置
A5: 5.1 中央空调外机 (奥克斯 ARV-X9 商用 VRF)
A6: HVAC-ODU-1F | B6: 空调 | C6: 空调外机 (1 楼专用) | D6: 奥克斯 | E6: AUX | F6: DLR-785W5/DCM-ARVX9 | G6: 1 | H6: 60000 | I6: =G6*H6 | J6: 超低温全直流变频 · 35.5kW · 57A · 带 10 台内机 | K6: 楼顶设备平台
A7: HVAC-ODU-2F | B7: 空调 | C7: 空调外机 (2 楼专用) | D7: 奥克斯 | E7: AUX | F7: DLR-1015W5/DCM-ARVX9 | G7: 1 | H7: 72000 | I7: =G7*H7 | J7: 超低温全直流变频 · 40.8kW · 64A · 带 12 台内机 | K7: 楼顶设备平台
A8: 5.2 空调网关 (Modbus TCP)
A9: HVAC-GW-1F | B9: 空调 | C9: 1F TCP 集控网关 | D9: 中弘 | E9: ZHONGHONG | F9: B 集控网关 TCP 款 | G9: 1 | H9: 1200 | I9: =G9*H9 | J9: MODBUS-TCP V3.2 · IP 192.168.50.51 · 64 内机上限 · DC 12V/1A 供电 · 直接接交换机 (省 USR-TCP232) | K9: 1F 弱电机柜
A10: HVAC-GW-2F | B10: 空调 | C10: 2F TCP 集控网关 | D10: 中弘 | E10: ZHONGHONG | F10: B 集控网关 TCP 款 | G10: 1 | H10: 1200 | I10: =G10*H10 | J10: 同上 · IP 192.168.50.52 · 挂 2F 外机 (12 内机 n=0..11) | K10: 2F 公共电箱 F201
A11: 5.3 中央空调内机 1F (10 台, 全直流式低静压风管机)
A12: HVAC-1F-1 | B12: 空调 | C12: 空调内机 (企业展位 #1) | D12: 奥克斯 | E12: AUX | F12: DLR-63F/DCDQH | G12: 1 | H12: 3000 | I12: =G11*H11 | J12: 1.8kW | K12: 1F 企业展位
A13: HVAC-1F-2 | B13: 空调 | C13: 空调内机 (企业展位 #2) | D13: 奥克斯 | E13: AUX | F13: DLR-63F/DCDQH | G13: 1 | H13: 3000 | I13: =G12*H12 | J13: 1.8kW | K13: 1F 企业展位
A14: HVAC-1F-3 | B14: 空调 | C14: 空调内机 (企业展位 #3) | D14: 奥克斯 | E14: AUX | F14: DLR-63F/DCDQH | G14: 1 | H14: 3000 | I14: =G13*H13 | J14: 1.8kW | K14: 1F 企业展位
A15: HVAC-1F-4 | B15: 空调 | C15: 空调内机 (直播间) | D15: 奥克斯 | E15: AUX | F15: DLR-71F/DCDQH | G15: 1 | H15: 3300 | I15: =G14*H14 | J15: 2kW | K15: 1F 直播间
A16: HVAC-1F-5 | B16: 空调 | C16: 空调内机 (外贸交易展示区 #1) | D16: 奥克斯 | E16: AUX | F16: DLR-71F/DCDQH | G16: 1 | H16: 3300 | I16: =G15*H15 | J16: 2kW | K16: 1F 外贸交易展示区
A17: HVAC-1F-6 | B17: 空调 | C17: 空调内机 (外贸交易展示区 #2) | D17: 奥克斯 | E17: AUX | F17: DLR-80F/DCDQH | G17: 1 | H17: 3500 | I17: =G16*H16 | J17: 2kW | K17: 1F 外贸交易展示区
A18: HVAC-1F-7 | B18: 空调 | C18: 空调内机 (园区展示) | D18: 奥克斯 | E18: AUX | F18: DLR-90F/DCDQH | G18: 1 | H18: 4000 | I18: =G17*H17 | J18: 2.2kW | K18: 1F 园区展示
A19: HVAC-1F-8 | B19: 空调 | C19: 空调内机 (路演发布洽谈区 #1) | D19: 奥克斯 | E19: AUX | F19: DLR-100F/DCDQH | G19: 1 | H19: 4500 | I19: =G18*H18 | J19: 2.2kW | K19: 1F 路演发布洽谈区
A20: HVAC-1F-9 | B20: 空调 | C20: 空调内机 (路演发布洽谈区 #2) | D20: 奥克斯 | E20: AUX | F20: DLR-112F/DCDQH | G20: 1 | H20: 5000 | I20: =G19*H19 | J20: 2.2kW | K20: 1F 路演发布洽谈区
A21: HVAC-1F-10 | B21: 空调 | C21: 空调内机 (企业综合展销区) | D21: 奥克斯 | E21: AUX | F21: DLR-125F/DCDQH | G21: 1 | H21: 5500 | I21: =G20*H20 | J21: 2.2kW | K21: 1F 企业综合展销区
A22: 5.4 中央空调内机 2F (12 台)
A23: HVAC-2F-11 | B23: 空调 | C23: 空调内机 (集团产业管理中心) | D23: 奥克斯 | E23: AUX | F23: DLR-90F/DCDQH | G23: 1 | H23: 4000 | I23: =G22*H22 | J23: 2.2kW | K23: 2F 集团产业管理中心
A24: HVAC-2F-12 | B24: 空调 | C24: 空调内机 (投资决策中心) | D24: 奥克斯 | E24: AUX | F24: DLR-90F/DCDQH | G24: 1 | H24: 4000 | I24: =G23*H23 | J24: 2.2kW | K24: 2F 投资决策中心
A25: HVAC-2F-13 | B25: 空调 | C25: 空调内机 (会议室) | D25: 奥克斯 | E25: AUX | F25: DLR-90F/DCDQH | G25: 1 | H25: 4000 | I25: =G24*H24 | J25: 2.2kW | K25: 2F 会议室
A26: HVAC-2F-14 | B26: 空调 | C26: 空调内机 (共享办公室 #1) | D26: 奥克斯 | E26: AUX | F26: DLR-90F/DCDQH | G26: 1 | H26: 4000 | I26: =G25*H25 | J26: 2.2kW | K26: 2F 共享办公室
A27: HVAC-2F-15 | B27: 空调 | C27: 空调内机 (共享办公室 #2) | D27: 奥克斯 | E27: AUX | F27: DLR-90F/DCDQH | G27: 1 | H27: 4000 | I27: =G26*H26 | J27: 2.2kW | K27: 2F 共享办公室
A28: HVAC-2F-16 | B28: 空调 | C28: 空调内机 (企业服务中心 #1) | D28: 奥克斯 | E28: AUX | F28: DLR-90F/DCDQH | G28: 1 | H28: 4000 | I28: =G27*H27 | J28: 2.2kW | K28: 2F 企业服务中心
A29: HVAC-2F-17 | B29: 空调 | C29: 空调内机 (企业服务中心 #2) | D29: 奥克斯 | E29: AUX | F29: DLR-90F/DCDQH | G29: 1 | H29: 4000 | I29: =G28*H28 | J29: 2.2kW | K29: 2F 企业服务中心
A30: HVAC-2F-18 | B30: 空调 | C30: 空调内机 (运营指挥中心 #1) | D30: 奥克斯 | E30: AUX | F30: DLR-90F/DCDQH | G30: 1 | H30: 4000 | I30: =G29*H29 | J30: 2.2kW | K30: 2F 运营指挥中心
A31: HVAC-2F-19 | B31: 空调 | C31: 空调内机 (运营指挥中心 #2) | D31: 奥克斯 | E31: AUX | F31: DLR-90F/DCDQH | G31: 1 | H31: 4000 | I31: =G30*H30 | J31: 2.2kW | K31: 2F 运营指挥中心
A32: HVAC-2F-20 | B32: 空调 | C32: 空调内机 (前厅 #1) | D32: 奥克斯 | E32: AUX | F32: DLR-100F/DCDQH | G32: 1 | H32: 4500 | I32: =G31*H31 | J32: 2.2kW | K32: 2F 前厅
A33: HVAC-2F-21 | B33: 空调 | C33: 空调内机 (前厅 #2) | D33: 奥克斯 | E33: AUX | F33: DLR-100F/DCDQH | G33: 1 | H33: 4500 | I33: =G32*H32 | J33: 2.2kW | K33: 2F 前厅
A34: HVAC-2F-22 | B34: 空调 | C34: 空调内机 (产业研究中心) | D34: 奥克斯 | E34: AUX | F34: DLR-100F/DCDQH | G34: 1 | H34: 4500 | I34: =G33*H33 | J34: 2.2kW | K34: 2F 产业研究中心
A35: 5.5 触摸屏线控器 (每台内机配 1 个)
A36: HVAC-CTRL | B36: 空调 | C36: 触摸屏线控器 | D36: 奥克斯 | E36: AUX | F36: XK10-DL-AUX (内销) | G36: 22 | H36: 200 | I36: =G35*H35 | J36: 每台内机配 1 个, 现场可手动操控 | K36: 各内机旁
A37: 本表合计 | I37: =SUM(I5:I36)

Sheet 6-网络
A1: 金湖展贸中心智能控制系统 · 6. 网络与电源配套
A2: BOM 物料明细 · 更新日期 2026-05-21
A4: 编号 | B4: 设备类别 | C4: 中文设备名 | D4: 厂家中文名 | E4: 厂家英文 | F4: 型号 | G4: 数量 | H4: 单价(¥) | I4: 小计(¥) | J4: 规格备注 | K4: 安装位置
A5: 6.1 核心网络设备
A6: NET-SW-1 | B6: 网络 | C6: 24 口千兆网管交换机 | D6: 华三 | E6: H3C | F6: S1224R | G6: 1 | H6: 1100 | I6: =G6*H6 | J6: 网管型 · VLAN 支持 · 1U 机架 | K6: 1F 弱电机柜
A7: NET-RT-1 | B7: 网络 | C7: 双 WAN 千兆路由器 | D7: 普联 | E7: TP-Link | F7: TL-ER605 | G7: 1 | H7: 450 | I7: =G7*H7 | J7: 5 千兆口 · 50 用户 · VPN | K7: 1F 弱电机柜
A8: 6.2 无线 (可选, 详见 docs/WIRELESS_NETWORK.md)
A9: NET-AP | B9: 网络 | C9: 吸顶 AP (POE 双频 WiFi) | D9: 普联 | E9: TP-Link | F9: CAP1750-PoE | G9: 4 | H9: 500 | I9: =G9*H9 | J9: WiFi5 双频 · POE · 室内 80-120㎡覆盖 | K9: 1F/2F 公共区域天花
A10: NET-AC | B10: 网络 | C10: AC 无线控制器 | D10: 普联 | E10: TP-Link | F10: AC500 | G10: 1 | H10: 1000 | I10: =G10*H10 | J10: 管理多台 AP · 集中配置 | K10: 1F 弱电机柜
A11: NET-POE-SW | B11: 网络 | C11: 16 口 POE 交换机 (替代/补充) | D11: 普联 | E11: TP-Link | F11: TL-SG2218P (16+2 POE 250W) | G11: 1 | H11: 1500 | I11: =G11*H11 | J11: 若选 POE 替代普通 24 口交换机 | K11: 1F 弱电机柜
A12: 6.3 不间断电源 UPS
A13: UPS-1 | B13: 网络 | C13: 不间断电源 UPS 1KVA | D13: 山特 | E13: SANTAK | F13: C1K | G13: 1 | H13: 1000 | I13: =G13*H13 | J13: 后备式 · 1000VA/600W · 主控+网络设备 | K13: 1F 弱电机柜底部
A14: 6.4 机柜与配电
A15: CAB-1 | B15: 网络 | C15: 12U 网络机柜 (600×600) | D15: 图腾 | E15: Toten | F15: 12U 网络机柜 | G15: 1 | H15: 1200 | I15: =G15*H15 | J15: 钢化玻璃门 · 4 风扇 · 落地式 | K15: 1F 主控室
A16: PDU-1 | B16: 网络 | C16: 8 位 PDU 电源分配 | D16: 图腾 | E16: Toten | F16: 8 位 1U PDU 16A | G16: 1 | H16: 200 | I16: =G16*H16 | J16: 机柜内统一供电 · 防雷 | K16: 机柜底部
A17: 本表合计 | I17: =SUM(I5:I16)

Sheet 7-线缆
A1: 金湖展贸中心智能控制系统 · 7. 线缆耗材
A2: BOM 物料明细 · 更新日期 2026-05-21
A4: 编号 | B4: 设备类别 | C4: 中文设备名 | D4: 厂家中文名 | E4: 厂家英文 | F4: 型号 | G4: 数量 | H4: 单价(¥) | I4: 小计(¥) | J4: 规格备注 | K4: 安装位置
A5: 7.1 网线
A6: NET-CAT5E | B6: 线缆 | C6: 超五类 Cat5e 网线 (室内) | D6: 安普/普睿 | E6: AMP/普睿 | F6: 超五类 屏蔽双绞 | G6: 200 | H6: 4 | I6: =G6*H6 | J6: 设备间互联 | K6: 弱电井
A7: NET-CAT6 | B7: 线缆 | C7: 超六类 Cat6 网线 (LED 长距离) | D7: 安普/普睿 | E7: AMP/普睿 | F7: 超六类 屏蔽 | G7: 100 | H7: 8 | I7: =G7*H7 | J7: LED 大屏接收卡长距离 | K7: 弱电井
A8: 7.2 DALI 与 RS485 信号线
A9: CAB-RVVP-DALI | B9: 线缆 | C9: RVVP 屏蔽双绞线 (DALI 总线) | D9: 远东/正泰 | E9: Far East/Chint | F9: RVVP 2×0.5mm² | G9: 200 | H9: 4 | I9: =G9*H9 | J9: DALI 总线 · 屏蔽层一端接地 | K9: 弱电井
A10: CAB-RVSP-485 | B10: 线缆 | C10: RVSP 屏蔽双绞线 (RS485) | D10: 远东/正泰 | E10: Far East/Chint | F10: RVSP 2×0.5mm² + 地 | G10: 100 | H10: 4 | I10: =G10*H10 | J10: USR-TCP232 ↔ CY-DALI64A · ITC/DSP 控制 | K10: 弱电井
A11: CAB-RVVP-XYE | B11: 线缆 | C11: RVVP 屏蔽双绞线 (空调 XYE 总线) | D11: 远东/正泰 | E11: Far East/Chint | F11: RVVP 3×0.75mm² | G11: 100 | H11: 5 | I11: =G11*H11 | J11: CCM-270B ↔ 外机/内机 XYE 通讯 | K11: 弱电井+楼顶
A12: 7.3 强电与音频线
A13: CAB-RVV6 | B13: 线缆 | C13: RVV 软线 2×6mm² (灯带大电流) | D13: 远东 | E13: Far East | F13: RVV 2×6mm² | G13: 80 | H13: 10 | I13: =G13*H13 | J13: 走廊 130m 灯带馈线 (大电流注入) | K13: 走廊吊顶
A14: CAB-RVV4 | B14: 线缆 | C14: RVV 软线 2×4mm² (灯带中电流) | D14: 远东 | E14: Far East | F14: RVV 2×4mm² | G14: 20 | H14: 7 | I14: =G14*H14 | J14: 灯箱馈线 | K14: 弱电井
A15: CAB-RVV25 | B15: 线缆 | C15: RVV 软线 2×2.5mm² | D15: 远东 | E15: Far East | F15: RVV 2×2.5mm² | G15: 40 | H15: 5 | I15: =G15*H15 | J15: 前厅灯带等 | K15: 电井
A16: CAB-RVV15 | B16: 线缆 | C16: RVV 软线 2×1.5mm² | D16: 远东 | E16: Far East | F16: RVV 2×1.5mm² | G16: 100 | H16: 3.5 | I16: =G16*H16 | J16: 小回路灯带 | K16: 电井
A17: CAB-RVS | B17: 线缆 | C17: RVS 双绞线 2×1.5mm² (喇叭线) | D17: 远东 | E17: Far East | F17: RVS 2×1.5mm² | G17: 200 | H17: 4 | I17: =G17*H17 | J17: 音响喇叭 | K17: 吊顶
A18: CAB-XLR | B18: 线缆 | C18: XLR 卡侬话筒线 OFC 屏蔽 | D18: 加纳美 | E18: — | F18: OFC 2 芯 + XLR 头 | G18: 50 | H18: 8 | I18: =G18*H18 | J18: DSP 麦克风信号线 | K18: 弱电井
A19: 7.4 接头与小件
A20: CONN-RJ45 | B20: 线缆 | C20: RJ45 水晶头 Cat5e/Cat6 | D20: 安普 | E20: AMP | F20: RJ45 水晶头 | G20: 100 | H20: 0.5 | I20: =G20*H20 | J20: 做网线头 | K20: 现场施工
A21: CONN-TEST | B21: 线缆 | C21: 网线测试仪 | D21: 任意 | E21: — | F21: 通用网线测线仪 | G21: 1 | H21: 50 | I21: =G21*H21 | J21: 验通断 | K21: 工具箱
A22: 本表合计 | I22: =SUM(I5:I21)

Sheet 8-工具
A1: 金湖展贸中心智能控制系统 · 8. 工具与调试
A2: BOM 物料明细 · 更新日期 2026-05-21
A4: 编号 | B4: 设备类别 | C4: 中文设备名 | D4: 厂家中文名 | E4: 厂家英文 | F4: 型号 | G4: 数量 | H4: 单价(¥) | I4: 小计(¥) | J4: 规格备注 | K4: 安装位置
A5: TOOL-1 | B5: 工具 | C5: 数字万用表 (调试) | D5: 优利德 | E5: UNI-T | F5: UT139C | G5: 1 | H5: 300 | I5: =G5*H5 | J5: 量电压/电阻/通断 | K5: 主控室
A6: TOOL-2 | B6: 工具 | C6: 网线压制钳 | D6: 任意 | E6: — | F6: RJ45 压线钳 | G6: 1 | H6: 80 | I6: =G6*H6 | J6: 做网线水晶头 | K6: 主控室
A7: TOOL-3 | B7: 工具 | C7: USB-RS485 转换器 | D7: 有人物联网 | E7: USR IoT | F7: USB-RS485 | G7: 1 | H7: 50 | I7: =G7*H7 | J7: 现场调试串口设备 | K7: 主控室
A8: TOOL-4 | B8: 工具 | C8: 螺丝刀套装 (一字+十字+精密) | D8: 世达 | E8: SATA | F8: 螺丝刀套装 | G8: 1 | H8: 150 | I8: =G8*H8 | J8: 端子/拨码用 | K8: 主控室
A9: TOOL-5 | B9: 工具 | C9: 剥线钳 | D9: 任意 | E9: — | F9: 弱电用剥线钳 | G9: 1 | H9: 50 | I9: =G9*H9 | J9: 处理弱电线 | K9: 主控室
A10: TOOL-6 | B10: 工具 | C10: 标签机 | D10: 兄弟 | E10: Brother | F10: PT-D210 | G10: 1 | H10: 400 | I10: =G10*H10 | J10: 设备/线缆标识 | K10: 主控室
A11: TOOL-7 | B11: 工具 | C11: Modbus Poll 软件 (Win) | D11: Modbus Tools | E11: Modbus Tools | F11: Modbus Poll 正版 | G11: 1 | H11: 800 | I11: =G11*H11 | J11: 寄存器调试 (HVAC/DALI), 可用试用版 | K11: 调试笔记本
A12: TOOL-8 | B12: 工具 | C12: Wireshark 抓包软件 | D12: 开源 | E12: Wireshark | F12: 开源免费 | G12: 1 | H12: 0 | I12: =G12*H12 | J12: 抓包排错 | K12: 调试笔记本
A13: 本表合计 | I13: =SUM(I5:I12)

Sheet 9-灯具
A1: 金湖展贸中心智能控制系统 · 9. 灯具一体化采购建议 (土建/装修预算)
A2: ⚠ 此 sheet 仅作采购建议, 由装修方采购; 灯具必须 0-10V 调光款 + AC 220V 输入 + CRI ≥ 80
A4: 编号 | B4: 品类 | C4: 中文规格 | D4: 品牌中文 | E4: 品牌英文 | F4: 推荐型号 | G4: 数量 | H4: 单价(¥) | I4: 小计(¥) | J4: 关键 spec | K4: 安装位置
A5: 9.1 LED 灯带 (8 路, 392m 总, DC 24V 接外置 HLG 电源)
A6: LIGHT-STRIP-1 | B6: 灯带 | C6: LED 灯带 24V (前厅 30m) | D6: 木林森 | E6: Mulinsen | F6: 5050 LED 24V 10W/m 暖白 3000K | G6: 30 | H6: 35 | I6: =G6*H6 | J6: CRI 80+ · IP20 · 单段 ≤5m · 5 年保 | K6: 1F 前厅吊顶
A7: LIGHT-STRIP-2 | B7: 灯带 | C7: LED 灯带 24V (展示区 15m) | D7: 木林森 | E7: Mulinsen | F7: 5050 LED 24V 10W/m 暖白 | G7: 15 | H7: 35 | I7: =G7*H7 | J7: 同上 | K7: 1F F101-R2
A8: LIGHT-STRIP-3 | B8: 灯带 | C8: LED 灯带 24V (园区 12m) | D8: 木林森 | E8: Mulinsen | F8: 5050 LED 24V 10W/m 暖白 | G8: 12 | H8: 35 | I8: =G8*H8 | J8: 同上 | K8: 1F F101-R3
A9: LIGHT-STRIP-4 | B9: 灯带 | C9: LED 灯带 24V (走廊 130m) | D9: 木林森 | E9: Mulinsen | F9: 5050 LED 24V 10W/m 中性 4000K | G9: 130 | H9: 35 | I9: =G9*H9 | J9: 走廊 IP54 防尘款 | K9: 1F 走廊吊顶
A10: LIGHT-STRIP-5 | B10: 灯带 | C10: LED 灯带 24V (R7 重点 80m) | D10: 木林森 | E10: Mulinsen | F10: 5050 LED 24V 10W/m 暖白 | G10: 80 | H10: 35 | I10: =G10*H10 | J10: CRI 80+ | K10: 1F F101-R7
A11: LIGHT-STRIP-6 | B11: 灯带 | C11: LED 灯带 24V (F102 企业展位 20m) | D11: 木林森 | E11: Mulinsen | F11: 5050 LED 24V 10W/m 暖白 | G11: 20 | H11: 35 | I11: =G11*H11 | J11: 同上 | K11: 1F F102
A12: LIGHT-STRIP-7 | B12: 灯带 | C12: LED 灯带 24V (F104 物贸 20m) | D12: 木林森 | E12: Mulinsen | F12: 5050 LED 24V 10W/m 暖白 | G12: 20 | H12: 35 | I12: =G12*H12 | J12: 同上 | K12: 1F F104
A13: LIGHT-STRIP-8 | B13: 灯带 | C13: LED 灯带 24V (2F 走廊 85m) | D13: 木林森 | E13: Mulinsen | F13: 5050 LED 24V 10W/m 中性 4000K | G13: 85 | H13: 35 | I13: =G13*H13 | J13: IP54 | K13: 2F 走廊吊顶
A14: 9.2 LED 筒灯 / 射灯 (10 路, ~150 盏, AC 220V + 0-10V 调光款)
A15: LIGHT-DL-1F-1 | B15: 筒灯 | C15: LED 筒灯 20W 0-10V 调光款 | D15: 欧普 | E15: OPPLE | F15: MK-A-20W (商照系列) | G15: 9 | H15: 120 | I15: =G15*H15 | J15: AC 220V · 0-10V · CRI 85 · 暖白 3000K · 开孔 90mm | K15: 1F F101-R2 (前厅周边)
A16: LIGHT-SL-1F-1 | B16: 射灯 | C16: LED 射灯 12W 0-10V 调光款 | D16: 欧普 | E16: OPPLE | F16: GD-A-12W | G16: 13 | H16: 90 | I16: =G16*H16 | J16: AC 220V · 0-10V · 24° 中角度 | K16: 1F F101-R2
A17: LIGHT-DL-1F-2 | B17: 筒灯 | C17: LED 筒灯 30W 0-10V (园区展示) | D17: 欧普 | E17: OPPLE | F17: MK-A-30W | G17: 14 | H17: 150 | I17: =G17*H17 | J17: AC 220V · 0-10V · 暖白 · 开孔 110mm | K17: 1F F101-R3
A18: LIGHT-DL-1F-3 | B18: 筒灯 | C18: LED 筒灯 20W 0-10V (走廊密集) | D18: 欧普 | E18: OPPLE | F18: MK-A-20W | G18: 29 | H18: 120 | I18: =G18*H18 | J18: 走廊 4000K 中性光 | K18: 1F F101-R5
A19: LIGHT-SL-1F-3 | B19: 射灯 | C19: LED 射灯 15W 0-10V | D19: 欧普 | E19: OPPLE | F19: GD-A-15W | G19: 10 | H19: 100 | I19: =G19*H19 | J19: 24° 中角度 4000K | K19: 1F F101-R5
A20: LIGHT-CL-1F-1 | B20: 吸顶 | C20: LED 吸顶灯 30W 0-10V | D20: 欧普 | E20: OPPLE | F20: 吸顶圆盘 30W | G20: 2 | H20: 180 | I20: =G20*H20 | J20: 走廊节点 AC 220V · 0-10V | K20: 1F F101-R6
A21: LIGHT-DL-1F-103 | B21: 筒灯 | C21: LED 筒灯 20W 0-10V | D21: 欧普 | E21: OPPLE | F21: MK-A-20W | G21: 7 | H21: 120 | I21: =G21*H21 | J21: 同上 | K21: 1F F103-R1
A22: LIGHT-SL-1F-103 | B22: 射灯 | C22: LED 射灯 15W 0-10V | D22: 欧普 | E22: OPPLE | F22: GD-A-15W | G22: 12 | H22: 100 | I22: =G22*H22 | J22: 展销区聚焦 | K22: 1F F103-R1
A23: LIGHT-DL-2F-1 | B23: 筒灯 | C23: LED 筒灯 20W 0-10V (2F 前厅) | D23: 欧普 | E23: OPPLE | F23: MK-A-20W | G23: 30 | H23: 120 | I23: =G23*H23 | J23: 密集排列 · 暖白 | K23: 2F F201-R1
A24: LIGHT-DL-2F-2 | B24: 筒灯 | C24: LED 筒灯 30W 0-10V (服务中心) | D24: 欧普 | E24: OPPLE | F24: MK-A-30W | G24: 10 | H24: 150 | I24: =G24*H24 | J24: 大瓦数高亮 | K24: 2F F201-R2
A25: LIGHT-DL-2F-3 | B25: 筒灯 | C25: LED 筒灯 20W 0-10V (服务中心 + 配房) | D25: 欧普 | E25: OPPLE | F25: MK-A-20W | G25: 16 | H25: 120 | I25: =G25*H25 | J25: 通用 | K25: 2F F201-R3
A26: LIGHT-SL-2F-3 | B26: 射灯 | C26: LED 射灯 15W 0-10V | D26: 欧普 | E26: OPPLE | F26: GD-A-15W | G26: 3 | H26: 100 | I26: =G26*H26 | J26: 展项聚焦 | K26: 2F F201-R3
A27: 9.3 LED 吸顶灯 / 面板灯 (3 路, 44 盏 2F 办公区)
A28: LIGHT-PL-2F-1 | B28: 面板 | C28: 600×600 LED 面板灯 60W 0-10V | D28: 欧普 | E28: OPPLE | F28: 面板灯 60W | G28: 13 | H28: 280 | I28: =G28*H28 | J28: 集成吊顶 600×600 · 自然光 4000K | K28: 2F F202 共享办公
A29: LIGHT-PL-2F-2 | B29: 面板 | C29: 600×600 LED 面板灯 60W 0-10V | D29: 欧普 | E29: OPPLE | F29: 面板灯 60W | G29: 16 | H29: 280 | I29: =G29*H29 | J29: 同上 | K29: 2F F203 产业研究
A30: LIGHT-PL-2F-3 | B30: 面板 | C30: 600×600 LED 面板灯 60W 0-10V | D30: 欧普 | E30: OPPLE | F30: 面板灯 60W | G30: 15 | H30: 280 | I30: =G30*H30 | J30: 同上 | K30: 2F F204 指挥中心
A31: 9.4 灯箱 LED 模组 (12 ㎡)
A32: LIGHT-LB-1 | B32: 灯箱 | C32: LED 灯箱模组 DC 24V 50W/㎡ | D32: 装修方定制 | E32: — | F32: 24V 恒压 LED 模组拼接 600W | G32: 1 | H32: 6000 | I32: =G32*H32 | J32: 装修方根据灯箱外壳尺寸定制 (12㎡ × ¥500/㎡) | K32: 1F F101-R3 灯箱位
A33: 9.5 格栅长条灯 (1 路, 35m, 0-10V 调光款)
A34: LIGHT-GR-1 | B34: 格栅 | C34: LED 格栅长条灯 20W/m 0-10V | D34: 三雄极光 | E34: PAK | F34: 格栅灯条 1.2m × 30 节 | G34: 30 | H34: 280 | I34: =G34*H34 | J34: 商照工程款 · AC 220V · 0-10V | K34: 1F F101-R7
A35: 本表合计 (灯具一体化) | I35: =SUM(I5:I34)
A37: ■ 重要说明
A38: 1. 此 sheet 的灯具采购**由装修/土建方负责**, 智能化方仅给规格建议. 此处单价 + 数量按现场实测数据估算, 实际以装修方报价为准.
A39: 2. 推荐欧普 OPPLE 商照系列 (灯具一线 + A 股上市 + 京东天猫遍地是), 雷士 NVC / 三雄极光 PAK / 西顿 CDN 同档替代.
A40: 3. ⚠ **所有筒灯/射灯/吸顶/面板灯采购合同必须明确写: "0-10V 调光款"**. 非调光款 / TRIAC 款无法接入我们的 LT-84A 系统.
A41: 4. 灯带按 DC 24V 10W/m 主流款采购, 木林森 / 国星光电 (国产 LED 芯片龙头) 是供应链上游, 性价比最高.
A42: 5. 灯箱 LED 模组由广告灯箱厂定制 (我们提供 12㎡ 面积 + 600W 总功率给厂家), 走 DC 24V 接 HLG-320H × 2.
...
